Workbook
Name ABEILLE: #REF!
Name abeillebrest: #REF!
Name ABEILLES: #REF!
Name ABEILLES2: #REF!
Name ABEILLES3: #REF!
Name AbeillesMRS: #REF!
Name aft: #REF!
Name aft: #REF!
Name aft: #REF!
Name aft: #REF!
Name aft: #REF!
Name aft: #REF!
Name aft: #REF!
Name aft: #REF!
Name aft: #REF!
Name aft: #REF!
Name aft: #REF!
Name aft: #REF!
Name aft: #REF!
Name aft: #REF!
Name aft: #REF!
Name aft: #REF!
Name arrondi_trim_inf: '[1]Trim calcul'!$F$3
Name arrondi_trim_inf: '[2]Trim calcul'!$F$3
Name arrondi_trim_sup: '[1]Trim calcul'!$F$2
Name arrondi_trim_sup: '[2]Trim calcul'!$F$2
Name Berth: [3]Main!$G$6
Name Berth: [3]Main!$G$6
Name Berth: [3]Main!$G$6
Name Berth: [3]Main!$G$6
Name Berth: [3]Main!$G$6
Name Berth: [3]Main!$G$6
Name Berth: [3]Main!$G$6
Name Berth: [3]Main!$G$6
Name Berth: [3]Main!$G$6
Name Berth: [4]Main!$G$6
Name Berth: #REF!
Name Berth: #REF!
Name Berth: #REF!
Name Berth: #REF!
Name Berth: [3]Main!$G$6
Name Berth: [3]Main!$G$6
Name Berth: [3]Main!$G$6
Name Berth: [3]Main!$G$6
Name Berth: [3]Main!$G$6
Name Berth: #REF!
Name Cargo: [3]Main!$C$7
Name Cargo: [3]Main!$C$7
Name Cargo: [3]Main!$C$7
Name Cargo: [3]Main!$C$7
Name Cargo: [3]Main!$C$7
Name Cargo: [3]Main!$C$7
Name Cargo: [3]Main!$C$7
Name Cargo: [3]Main!$C$7
Name Cargo: [3]Main!$C$7
Name Cargo: [4]Main!$C$7
Name Cargo: #REF!
Name Cargo: #REF!
Name Cargo: #REF!
Name Cargo: #REF!

Sheet Data Entry
B1: CFOOP XX - Cargo Documents | E1: Version 2
E2: 01/01/2026
I6: Instructions
A8: Vessel | I8: Name of the vessel. Should be the registered name without "S/V" of "M/V"
B10: Import Voyage | C10: Export Voyage
A11: Voyage: | I11: "Import voyage number" should be the number of the voyage ending on arrival. "Export voyage number" should be the next voyage number
A13: Charterer | I13: Name of the Charterer as per Charter Party, if any
A15: C/P Date | I15: Date of signature of the Charter Party, if any
A17: Loading Port and country: | I17: Name of the port and country
A19: Terminal: | I19: Name of Terminal
A21: Dockers: | I21: Name of the Docker's Company
A23: Berth: | I23: Name of the Berth
C24: Nominated Quantity
A25: Cargo: | I25: Cargo should the one designated on the Bill of Ladding or Charter Party
A27: Surveyor: | I27: Name of the cargo surveyor, if any
A29: Agency: | I29: Name of the Agent and sub-agent, if any
A31: Broker: | I31: Name of the cargo broker, if any
A33: Disponent Owner: | I33: Name of the Commercial Ship Owner
A35: Master: | I35: Name of the Master

Sheet SOF
C1: STATEMENT OF FACTS | J1: Page 1 of 1 | K1: PRT 012 | L1: Page 1 of 1 | O1: Instructions
I2: Version | J2: 2 | K2: Rev : 02 | L2: 42917
I3: Date | J3: 01/01/2026 | O3: To be signed by Master only. Agent or Terminal SOF should be same as Ship's SOF. Do not hesitate to coordinate in advance for having the same timings. Other SOF should be signed only by Master with the mention "For receipt only without prejudice. Ref Ship's SOF". Any delay, start/stop of cargo operations and cause should be documented and letter of Protest should be issued accordingly. Usually the SOF is signed after cargo operation and lines from Pilot onboard to SOSP can be added by hand. No blank should be left between lines, including in the Date colomn.
A4: Vessel: | B4: =IF('Data Entry'!B8="","",'Data Entry'!B8) | D4: Voyage No: | E4: Import | F4: Export | G4: Port : | H4: =IF('Data Entry'!B17="","",'Data Entry'!B17) | K4: R.O.B.
E5: =IF('Data Entry'!B11="","",'Data Entry'!B11) | F5: =IF('Data Entry'!C11="","",'Data Entry'!C11) | K5: HFO | L5: MGO
I6: Date | J6: Time (LT)
A7: EOSP | I7: 46018 | J7: 0.375
A8: NOTICE OF READINESS TENDERED | I8: " | J8: 0.375
A9: PILOT ONBOARD | I9: " | J9: 0.375
A10: FIRST LINE ASHORE / COMMENCE MOORING | I10: " | J10: 0.45833333
A11: ALL FAST | I11: " | J11: 0.47222222
A12: NOTICE OF READINESS RE-TENDERED - WITHOUT PREJUDICE | I12: " | J12: 0.64583333
A13: GANGWAY IN POSITION | I13: " | J13: 0.79166667
A14: PILOT OFF | I14: 45685 | J14: 0.47916667
A15: INWARD CLEARANCE GRANTED | I15: " | J15: 0.54166667
A16: FWD & AFT CARGO HATCH OPEN | I16: " | J16: 0.55902778
A17: DOCKERS ONBOARD | I17: " | J17: 0.60416667
A18: COMMENCED DISCHARGING | I18: " | J18: 0.61805556
A19: DISCHARGING SUSPENDED - SHIP STOP FOR USCG PSC DRILLS | I19: " | J19: 0.625
A20: DISCHARGING RESUMED | I20: " | J20: 0.63194444
A21: DISCHARGING SUSPENDED - SHORE STOP FOR DOCKERS BREAK. | I21: " | J21: 0.63611111
A22: DISCHARGING RESUMED | I22: " | J22: 1520
A23: DISCHARGING SUSPENDED - SHORE STOP END OF WORKING DAY | I23: " | J23: 1617
A24: ALL HATCHES CLOSED AND LOCKED BY CREW | I24: " | J24: 1638 | O24: Mandatory items:
A25: HATCHES OPENED AND CRANES TESTED BY CREW | I25: " | J25: 1642 | O25: EOSP (End of Sea Passage)
A26: DOCKERS ONBOARD | I26: " | J26: 1705 | O26: SOSP (Start of Sea Passage) also known as COSP (Commence of Sea Passage)
A27: DISCHARGING RESUMED | I27: 45686 | J27: 630 | O27: Free pratique granted
A28: … | I28: " | J28: 800 | O28: Notice of Readiness RE-Tendered - Without prejudice
A29: DISCHARGING COMPLETED | I29: " | J29: 805 | O29: Pilot onboard
A30: … | O30: Pilot off
A31: PILOT ON BOARD | O31: Tug made fast / escorting - Name of the tug
A32: LAST LINE | O32: Tug cast off
A33: PILOT OUT | O33: Tug free
A34: SOSP | O34: First line ashore
O35: All fast
O36: Commence unmooring
O37: All clear
O38: Anchored
O39: Anchor aweigh
O40: Ship's / Shore gangway rigged
...

Sheet NOR
F1: NOTICE OF READINESS | S1: Page 1 of 1 | X1: Instructions
P2: Version 2 | S2: 01/01/2026
X3: Notice of Readiness should be tendered by e-mail to the Agent with the same wording as this NOR and request the Agent to follow up this notice to any party involved in the cargo operations. Subject of this e-mail should be clear and contains "Notice of Readiness" and the navire of the vessel. If any other e-mail of involved parties are know, such as Charterer, Broker, Terminal, add them. Operation@towt.eu should in copy of this e-mail When and where the NOR to be tendered? At pilot boarding ground or in vicinity of such location even if the vessel is instructed to proceed to anchorage. NOR should be retendered in several cases in order to be sure of at least one will be valid. Please check NOR RT tab. A hard copy, signed by Master, should be signed and stamped by terminal. How to fill this form? "roads/at berth/anchorage": remove the unproper cases. Dates should be explicit: avoid "02/01/2025", prefer "02 JAN 2025" to avoid misinterpretation between 01 FEB 2025 and 02 JAN 2025. Name of the cargo should be same as the cargo instructed to be loaded or the same as stated on BLs. "Pallets" or "bags" is not valid.
A4: To: | M4: Vessel: | P4: =IF('Data Entry'!B8="","",'Data Entry'!B8)
B5: =IF('Data Entry'!B19="","",'Data Entry'!B19) | M5: Voyage No:
B6: =IF('Data Entry'!B29="","",'Data Entry'!B29) | M6: Port: | P6: =IF('Data Entry'!B17="","",'Data Entry'!B17)
B7: =IF('Data Entry'!B33="","",'Data Entry'!B33) | M7: Berth: | P7: =IF('Data Entry'!B23="","",'Data Entry'!B23)
B8: =IF('Data Entry'!B31="","",'Data Entry'!B31) | M8: Chrtr Ref. Nbr: | P8: C/P
B9: To whom it may concern
A12: Dear Sirs,
B13: I hereby confirm that | F13: ='Data Entry'!B8 -> 0 | I13: , under my command, has arrived on roads/at berth/anchorage of
F14: (Vessel Name)
B15: ='Data Entry'!B17 -> 0 | I15: on the
B16: (Port, Country) | K16: (Date & Time)
B17: And she is in all respects ready to load / discharge the cargoes of :
B18: ='Data Entry'!B25 -> 0
B19: (Cargo Designation)
B20: in accordance with the terms and conditions of Charter Party dated | P20: =IF("'Data Entry'!C10"="","",'Data Entry'!B15) -> 0
P21: (C/P date)
B22: and any addendum thereto.
B24: Notice of Readiness tendered on the | J24: =K15 -> 0
J25: (Date & Time)
O28: Yours faithfully,
O33: ='Data Entry'!B35 -> 0
O34: Master
G37: Accepted By:
G38: Date:
G39: Time:
G41: Signature:

Sheet NOR (MOGAS)
G2: NOTICE OF READINESS | M2: PRT 001 | N2: Page 1 of 1
M3: Rev: 02 | N3: 42917
C5: To: | E5: Barge ATLANTIS | J5: Vessel: | L5: ATRIA
E6: TO WHOM IT MAY CONCERN | J6: Voyage No: | L6: ='Data Entry'!B11 -> 0
E7: VITOL SA | J7: Port: | L7: ='Data Entry'!B13 -> 0
J8: Chrtr Ref. Nbr: | L8: C/P 28 Nov 2018
C12: Dear Sirs,
C13: I hereby confirm that | F13: M/T ATRIA | J13: , under my command, has arrived in Rotterdam, NL
F14: (Vessel Name)
C15: at 17:48 LT on the 01st of December 2018 and tendering the Notice of Readiness for
C17: ='Data Entry'!B13 -> 0 | G17: on | H17: 01 DECEMBER 2018 at 17:48 Lt
C18: (Port, Country) | H18: (Date & Time) | L18: ACAP 4300 MT of GASOLINE
C19: And she is in all respects ready to load the cargo of :
L20: (Cargo Grade & Qty)
C21: in accordance with the terms and conditions of Charter Party dated | M21: 43432
M22: (CP Date)
C23: and any addendum thereto.
C29: Yours faithfully,
D32: CAPT T. HEMON
D33: Master
E35: Accepted By:
E36: Date:
E37: Time:
E39: Signature:

Sheet NOR RT (MOGAS)
G2: RE-TENDERING NOTICE OF READINESS | M2: PRT 001A | N2: Page 1 of 1
M3: Rev: 02 | N3: 42917
C5: To: | E5: ='NOR (MOGAS)'!E5 -> Barge ATLANTIS | J5: Vessel: | L5: ATRIA
E6: =NOR!B5 | J6: Voyage No: | L6: =NOR!P5 -> 0
E7: =IF(NOR!B6="","",NOR!B6) | J7: Port: | L7: =NOR!P6
E8: =IF(NOR!B7="","",NOR!B7) | J8: Chrtr Ref. Nbr: | L8: =NOR!P7
E9: =IF(NOR!#REF!="","",NOR!#REF!) -> #REF!
C12: Dear Sirs,
C13: I hereby confirm that | F13: M/T ATRIA | J13: =NOR!K13 -> 0 | R13: anchorage of
F14: (Vessel Name)
C15: =NOR!#REF! -> #REF!
C16: =NOR!B15 -> 0 | G16: on | H16: =NOR!K15 -> 0
C17: (Port, Country) | H17: (Date & Time) | L17: ='NOR (MOGAS)'!L18 -> ACAP 4300 MT of GASOLINE
C18: And she is now in all respects ready to load the cargo of :
L19: (Cargo Grade & Qty)
C20: in accordance with the terms and conditions of Charter Party dated | M20: =NOR!P20 -> 0
M21: (CP Date)
C22: and any addendum thereto.
C25: I, hereby re-tender NOR without prejudice to any NOR tendered earlier, on the below dates/times:-
D26: 01Dec2018; 20:24 LT | K26: ALL FAST / NOR RE-TENDERED
D27: 02Dec2018; 15:24 LT | K27: BARGE FAST / NOR RE-TENDERED
C34: Yours faithfully,
D37: =NOR!O33 -> 0
D38: Master
E40: Accepted By:
E41: Date:
E42: Time:
E44: Signature:

Sheet NOR (GASOIL)
G2: NOTICE OF READINESS | M2: PRT 001 | N2: Page 1 of 1
M3: Rev: 02 | N3: 42917
C5: To: | E5: Barge GERVAIS | J5: Vessel: | L5: ATRIA
E6: TO WHOM IT MAY CONCERN | J6: Voyage No: | L6: =NOR!P5 -> 0
E7: VITOL SA | J7: Port: | L7: =NOR!P6
J8: Chrtr Ref. Nbr: | L8: =NOR!P7
C12: Dear Sirs,
C13: I hereby confirm that | F13: M/T ATRIA | J13: , under my command, has arrived in Rotterdam, NL
F14: (Vessel Name)
C15: at 17:48 LT on the 01st of December 2018 and tendering the Notice of Readiness for
C17: ='Data Entry'!B13 -> 0 | G17: on | H17: 01 DECEMBER 2018 at 17:48 Lt
C18: (Port, Country) | H18: (Date & Time) | L18: ACAP 800 MT of GASOIL
C19: And she is in all respects ready to load the cargo of :
L20: (Cargo Grade & Qty)
C21: in accordance with the terms and conditions of Charter Party dated | M21: 43432
M22: (CP Date)
C23: and any addendum thereto.
C29: Yours faithfully,
D32: CAPT T. HEMON
D33: Master
E35: Accepted By:
E36: Date:
E37: Time:
E39: Signature:

Sheet NOR RT (GASOIL)
G2: RE-TENDERING NOTICE OF READINESS | M2: PRT 001A | N2: Page 1 of 1
M3: Rev: 02 | N3: 42917
C5: To: | E5: ='NOR (GASOIL)'!E5 -> Barge GERVAIS | J5: Vessel: | L5: ATRIA
E6: =NOR!B5 | J6: Voyage No: | L6: =NOR!P5 -> 0
E7: =IF(NOR!B6="","",NOR!B6) | J7: Port: | L7: =NOR!P6
E8: =IF(NOR!B7="","",NOR!B7) | J8: Chrtr Ref. Nbr: | L8: =NOR!P7
E9: =IF(NOR!#REF!="","",NOR!#REF!) -> #REF!
C12: Dear Sirs,
C13: I hereby confirm that | F13: M/T ATRIA | J13: =NOR!K13 -> 0 | R13: anchorage of
F14: (Vessel Name)
C15: =NOR!#REF! -> #REF!
C16: =NOR!B15 -> 0 | G16: on | H16: =NOR!K15 -> 0
C17: (Port, Country) | H17: (Date & Time) | L17: ='NOR (GASOIL)'!L18 -> ACAP 800 MT of GASOIL
C18: And she is now in all respects ready to load the cargo of :
L19: (Cargo Grade & Qty)
C20: in accordance with the terms and conditions of Charter Party dated | M20: =NOR!P20 -> 0
M21: (CP Date)
C22: and any addendum thereto.
C25: I, hereby re-tender NOR without prejudice to any NOR tendered earlier, on the below dates/times:-
D26: 01Dec2018; 20:24 LT | K26: ALL FAST / NOR RE-TENDERED
D27: 02Dec2018; 09:00 LT | K27: NOR RE-TENDERED
D28: 03Dec2018; 09:00 LT | K28: NOR RE-TENDERED
D29: 04Dec2018; 09:00 LT | K29: NOR RE-TENDERED
D30: 05Dec2018; 09:00 LT | K30: NOR RE-TENDERED
D31: 05Dec2018; 16:30 LT | K31: BARGE FAST / NOR RE-TENDERED
C34: Yours faithfully,
D37: =NOR!O33 -> 0
D38: Master
E40: Accepted By:
E41: Date:
E42: Time:
E44: Signature:

Sheet NOR RT
F1: NOTICE OF READINESS RE-TENDERED | S1: Page 1 of 1 | Y1: Instructions
P2: Version 2 | S2: 01/01/2026
Y3: In addition to the first Notice of Readiness (See NOR tab) some additionnal notices of readiness are tendered: - Arrival at contingency anchorage (Anchored) - Start of working day 09:00 LT - Arrival at berth (All fast) - Free Pratique granted (if not granted on arrival) - Ready to load if discharging took place before (after completion of hold cleaning or immediately after the last pallet was discharged. Rentendered Notice of Readiness should be sent by e-mail to the Agent with the same wording as this NOR Retendered and request the Agent to follow-up this notice to any party involved in the cargo operations. Subject of this e-mail should be clear and contains "Notice of Readiness Retendered" and the navire of the vessel. If any other e-mail of involved parties are know, such as Charterer, Broker, Terminal, add them. Operation@towt.eu should in copy of this e-mail Retendered NOR should state "without prejudice to any previous NOR tendered" A hard copy as a racap of all e-mails sent, signed by Master, should also be signed and stamped by terminal
A4: To: | M4: Vessel: | P4: =IF('Data Entry'!B8="","",'Data Entry'!B8)
B5: =IF('Data Entry'!B19="","",'Data Entry'!B19) | M5: Voyage No:
B6: =IF('Data Entry'!B29="","",'Data Entry'!B29) | M6: Port: | P6: =IF('Data Entry'!B17="","",'Data Entry'!B17)
B7: =IF('Data Entry'!B33="","",'Data Entry'!B33) | M7: Berth: | P7: =IF('Data Entry'!B23="","",'Data Entry'!B23)
B8: =IF('Data Entry'!B31="","",'Data Entry'!B31) | M8: Chrtr Ref. Nbr: | P8: C/P
B9: To whom it may concern
A12: Dear Sirs,
B13: I hereby confirm that | F13: ARTEMIS | I13: , under my command, has arrived at roads / berth / anchorage of
F14: (Vessel Name)
B15: ='Data Entry'!B17 -> 0 | I15: on the
B16: (Port, Country) | K16: (Date & Time)
B17: And she is in all respects ready to load / discharge the cargo of :
B18: =NOR!B18 -> 0
B19: (Cargo Designation)
B20: in accordance with the terms and conditions of Charter Party dated | P20: ='Data Entry'!B15 -> 0
P21: (C/P date)
B22: and any addendum thereto.
A25: I, hereby Re-Tender NOR without prejudice to any previous NOR tendered, on the below dates / times :
B26: 24 DEC 2025 08:00 LT | I26: DROPPED ANCHOR
B27: 24 DEC 2025 09:00 LT | I27: START OF WORKING DAY
B28: 24 DEC 2025 18:00 LT | I28: ALL FAST AT BERTH
B29: 24 DEC 2025 20:00 LT | I29: FREE PRATIQUE GRANTED
O37: Yours faithfully,
O41: =NOR!O33 -> 0
O42: Master
F45: Accepted By:
F46: Date:
F47: Time:
F49: Signature:

Sheet Holds Certificate
F1: HOLDS READINESS PRIOR LOADING | S1: Page 1 of 1 | Y1: Instructions
P2: Version 2 | S2: 01/01/2026
Y3: Chief Officer or Master can sign this certificate. If you are not sure, ask Master. Do not load cargo before having a hard copy of this certificate signed and stamped by the terminal of a surveyor. If a hold is not ready to load, do not accept any mention on a Hold readiness certificate. Prefer to remove the designation of the hold not ready and then clean the hold and request a new inspection later. After the second inspection try to obtain a certificate signed with all the holds mentionned. If not possible, only with the designation of the hold re-inspected.
A4: To: | M4: Vessel: | P4: =IF('Data Entry'!B8="","",'Data Entry'!B8)
B5: =IF('Data Entry'!B19="","",'Data Entry'!B19) | M5: Voyage No:
B6: =IF('Data Entry'!B29="","",'Data Entry'!B29) | M6: Port: | P6: =IF('Data Entry'!B17="","",'Data Entry'!B17)
B7: =IF('Data Entry'!B33="","",'Data Entry'!B33) | M7: Berth: | P7: =IF('Data Entry'!B23="","",'Data Entry'!B23)
B8: =IF('Data Entry'!B31="","",'Data Entry'!B31) | M8: Chrtr Ref. Nbr: | P8: C/P
B9: To whom it may concern
B13: Dear Sirs,
B14: This is to certify that the undersigned, duly appointed by the cargo supplier, after having inspected the holds
B15: following Cargo holds:
B16: Upper fore, Middle Fore, Lower Fore, Upper aft, Middle aft, Lower aft
B17: (Cargo holds designation)
B19: has found them free of pest, remains of waste or residues, odours, and fit to receive the nominated cargo of
B20: ='Data Entry'!B25 -> 0
B21: (Cargo grade)
B34: Surveyor | P34: Master/Chief Officer

Sheet KM1
E2: KEY TRANSFER MEETING | M2: PRT 011 | N2: Page 1 of 1
M3: Rev : 02 | N3: 42917
B5: Vessel | C5: =NOR!P4 | F5: Port | G5: ='Data Entry'!B13 -> 0 | L5: Voy No | M5: ='Data Entry'!B11 -> 0
B7: Terminal | C7: ='Data Entry'!B19 -> 0 | F7: Berth | G7: ='Data Entry'!B23 -> 0 | L7: Date | M7: =#REF! -> #REF!
B9: Vessel Information | I9: Terminal Information
B10: No. and Size of Manifolds | E10: 3 x 16" | I10: No. & Size of Connections
E11: ='Data Entry'!B25 -> 0 | L11: =E11 -> 0
B12: SIMULTANEOUS Cargo Transfer Rates | D12: Initial | E12: 500 m3/h | F12: 300 m3/h | I12: SIMULTANEOUS Cargo Transfer Rates (or) Manifold Pressure | K12: Initial | L12: 500 m3/h | M12: 300 m3/h
D13: Bulk | E13: 1000 m3/h or 10Bar | F13: 1000 m3/h or 10Bar | K13: Bulk | L13: 1000 m3/h or 10Bar | M13: 1000 m3/h or 10Bar
D14: Final | E14: 500 m3/h | F14: 300 m3/h | K14: Final | L14: 500 m3/h | M14: 300 m3/h
B15: NON-SIMULTANEOUS Cargo Transfer Rates | D15: Initial | E15: 500 m3/h (3100 Bbls/h) | I15: NON- SIMULTANEOUS Cargo Transfer Rates (or) Manifold Pressure | K15: Initial
D16: Bulk | E16: 3000 m3/h (18800 Bbls/h) or 10Bar | K16: Bulk
D17: Final | E17: 500 m3/h (3100 Bbls/h) | K17: Final
B18: Emergency Signal by Vessel | E18: One (1) Long Blast / "STOP" 3x Shore Radio | I18: Emergency Signal by Terminal
B19: Notice for Immediate Stoppage | E19: N/A - LOADING | I19: Notice for Immediate Stoppage
B20: Notice for Rate Reduction | E20: N/A - LOADING | I20: Notice for Rate Reduction
B21: Tanks to COW | E21: N/A | I21: Cargo Dens.& Temp
B22: Vessel Experience Factor | E22: 0.9986 | I22: Shore Line size and length
I23: Shore tanks number
I24: Line Displacement Requirement
I25: Ship/Shore Communication
C26: Cargo History | I26: Back-Up Communication
C27: Cargo Grade | E27: Tanks Loaded | I27: Emergency Shutdown Procedure
B28: Last | C28: SEE LAST 3 CARGO LIST | I28: Material Safety Data Sheet | L28: YES
B29: 2nd Last | I29: Method of arm/hose draining
B30: 3rd Last | I30: Manifold height above water
I31: Max Depth/Draft at Berth
B33: Cargo Stoppage by: (Ship/Shore) | H33: Cargo Grade as per B/L | J33: ='Data Entry'!B25 -> 0
H34: Terminal's Nomination
H35: Vessels Nomination | J35: Maximum 30504 MT
B36: Watch Keeping Schedule
B37: Time ® | C37: 00-04 / 12-24 | E37: 04-08 / 16-20 | G37: 08-12 / 20-24
B38: D/Officer | C38: 2/O V. Negajs | E38: 2/O V. Izmodenovs | G38: 2/O E. Orfano
B39: Crew | C39: AB1 J. Obtial | E39: AB2 K. Dela Cruz | G39: AB3 W. Diao
B40: Crew | C40: OS Longakit | E40: Wiper Pacure | G40: BSN O. Abenoja
B43: Drafts (m) | C43: Ford | D43: Aft | E43: M'ship | I43: Master's Name | K43: =NOR!O33 -> 0
B44: Arrival | C44: 6 | D44: 6.8 | E44: 6.4 | F44: SW | I44: Chief Engineer's Name | K44: V. Volkovs
B45: Departure | C45: 10.35 | D45: 10.35 | E45: 10.35 | F45: SW | I45: Chief Officer's Name | K45: MADelgado
B47: Tide | I47: Remarks:
B48: Date/Time | C48: Ht. of tide | D48: Date/Time | E48: Ht. of tide | F48: Date/Time | G48: Ht. of tide
...

Sheet PUMPLOG (4)
G2: PUMPING LOG | W2: PRT 010 | Z2: Page 1 of 1
W3: Rev: 02 | Z3: 42917
C5: Vessel: | D5: ATRIA | L5: Port: | M5: ='Data Entry'!B13 -> 0 | V5: Terminal: | W5: ='Data Entry'!B19 -> 0
H6: Date/Time Hose connected: | I6: 43009.188 | W6: Date/Time Commenced Pumping: | X6: 43009.904
E7: Nbr of Hoses: | F7: 1 | K7: Dia of Hoses: | L7: 10" | S7: Dia of Shore line: | T7: 12" | Z7: Dist to shore tank: | AA7: 0.5km
H8: Date/Time Comptd Pumping: | I8: 43011.012 | W8: Date Time Hose disconnected: | X8: 43011.021
P9: Max Rate permitted by receiving facility: | Q9: GNA 95 - 500 M3/HR
P10: Max Pressure permitted by receiving facility: | Q10: 8 Bar
P11: Any other restrictions by receiving facility:
B13: PRESSURE GAUGE TO BE PLACED OUT OF SHIP’S MANIFOLD VALVE - PRESSURE IN BAR / PSI (Strike out one)
B15: Date | D15: Pressure at Ship Rail | N15: Discharge Rate | O15: Temp. | S15: Remarks | AA15: Ch/Off Initials
D16: Manifold Number | O16: Air | Q16: Cargo
B17: Time | F17: #4 | O17: °C | Q17: °C
B18: 0.90416667 | F18: 0 | O18: 23 | Q18: 22 | S18: Commenced loading GNA 95 | AA18: KG
B19: 0.91666667 | F19: 0 | N19: 0 | O19: 23 | Q19: 22 | AA19: KG
B20: 0.95833333 | F20: 0 | N20: 134 | O20: 22 | Q20: 22 | AA20: KG
B21: 1 | F21: 0 | N21: 461 | O21: 22 | Q21: 22 | AA21: KG
B22: 0.041666667 | F22: 0 | N22: 435 | O22: 22 | Q22: 23 | AA22: IM
B23: 0.083333333 | F23: 0 | N23: 454 | O23: 22 | Q23: 23 | AA23: IM
B24: 0.125 | F24: 0 | N24: 446 | O24: 22 | Q24: 23 | AA24: IM
B25: 0.16666667 | F25: 0 | N25: 451 | O25: 22 | Q25: 23 | AA25: IM
B26: 0.20833333 | F26: 0 | N26: 452 | O26: 23 | Q26: 23 | AA26: JS
B27: 0.25 | F27: 0 | N27: 464 | O27: 23 | Q27: 23 | AA27: JS
B28: 0.29166667 | F28: 0 | N28: 457 | O28: 24 | Q28: 23 | AA28: JS
B29: 0.33333333 | F29: 0 | N29: 477 | O29: 24 | Q29: 23 | AA29: JS
B30: 0.375 | F30: 0 | N30: 475 | O30: 24 | Q30: 23 | AA30: KG
... B45: 1 | F45: 0 | N45: 467 | O45: 26 | Q45: 24 | AA45: KG
B46: 0.0125 | F46: 0 | N46: 123 | O46: 26 | Q46: 24 | S46: Completed loading GNA 95 | AA46: IM
S47: SHORE STOP
B50: Terminal | I50: Cargo Surveyor | Q50: Chief Mate | X50: Master

Sheet PUMPLOG (3)
G2: PUMPING LOG | W2: PRT 010 | Z2: Page 1 of 1
W3: Rev: 02 | Z3: 42917
C5: Vessel: | D5: ATRIA | L5: Port: | M5: ='Data Entry'!B13 -> 0 | V5: Terminal: | W5: ='Data Entry'!B19 -> 0
H6: Date/Time Hose connected: | I6: 43009.188 | W6: Date/Time Commenced Pumping: | X6: 43008.046
E7: Nbr of Hoses: | F7: 1 | K7: Dia of Hoses: | L7: 10" | S7: Dia of Shore line: | T7: 12" | Z7: Dist to shore tank: | AA7: 0.5km
H8: Date/Time Comptd Pumping: | I8: 43009.883 | W8: Date Time Hose disconnected: | X8: 43011.021
P9: Max Rate permitted by receiving facility: | Q9: GNA 98 - 500 M3/HR
P10: Max Pressure permitted by receiving facility: | Q10: 8 Bar
P11: Any other restrictions by receiving facility:
B13: PRESSURE GAUGE TO BE PLACED OUT OF SHIP’S MANIFOLD VALVE - PRESSURE IN BAR / PSI (Strike out one)
B15: Date | D15: Pressure at Ship Rail | N15: Discharge Rate | O15: Temp. | S15: Remarks | AA15: Ch/Off Initials
D16: Manifold Number | O16: Air | Q16: Cargo
B17: Time | F17: #4 | O17: °C | Q17: °C
B18: 0.19583333 | F18: 0 | S18: Commenced loading GNA 98 | AA18: VV
B19: 0.20833333 | F19: 0 | N19: 61 | O19: 22 | Q19: 23 | AA19: JS
B20: 0.25 | F20: 0 | N20: 442 | O20: 22 | Q20: 23 | AA20: JS
B21: 0.29166667 | F21: 0 | N21: 432 | O21: 22 | Q21: 23 | AA21: JS
B22: 0.33333333 | F22: 0 | N22: 432 | O22: 22 | Q22: 23 | AA22: JS
B23: 0.375 | F23: 0 | N23: 428 | O23: 22 | Q23: 22 | AA23: KG
B24: 0.41666667 | F24: 0 | N24: 435 | O24: 23 | Q24: 22 | AA24: KG
B25: 0.45833333 | F25: 0 | N25: 432 | O25: 23 | Q25: 22 | AA25: KG
B26: 0.5 | F26: 0 | N26: 429 | O26: 24 | Q26: 22 | AA26: KG
B27: 0.54166667 | F27: 0 | N27: 432 | O27: 24 | Q27: 22 | AA27: IM
B28: 0.58333333 | F28: 0 | N28: 428 | O28: 24 | Q28: 23 | AA28: IM
B29: 0.625 | F29: 0 | N29: 427 | O29: 25 | Q29: 23 | AA29: IM
B30: 0.66666667 | F30: 0 | N30: 427 | O30: 25 | Q30: 23 | AA30: IM
B31: 0.70833333 | F31: 0 | N31: 426 | O31: 25 | Q31: 24 | S31: 17:30- Suspended loading shore order | AA31: JS
B32: 0.75 | F32: 0 | N32: 120 | O32: 25 | Q32: 24 | AA32: JS
B33: 0.79166667 | F33: 0 | N33: 0 | O33: 25 | Q33: 24 | S33: 19:18 - Resumed loading | AA33: JS
B34: 0.83333333 | F34: 0 | N34: 256 | O34: 24 | Q34: 24 | AA34: JS
B35: 0.88333333 | F35: 0 | N35: 464 | O35: 24 | Q35: 24 | S35: 21:12 Completed loading GNA 98 | AA35: KG
S36: SHORE STOP
AA41: JS
B45: Terminal | I45: Cargo Surveyor | Q45: Chief Mate | X45: Master

Sheet PUMPLOG (2)
G2: PUMPING LOG | W2: PRT 010 | Z2: Page 1 of 1
W3: Rev: 02 | Z3: 42917
C5: Vessel: | D5: ATRIA | L5: Port: | M5: ='Data Entry'!B13 -> 0 | V5: Terminal: | W5: ='Data Entry'!B19 -> 0
H6: Date/Time Hose connected: | I6: 43008.042 | W6: Date/Time Commenced Pumping: | X6: 43008.046
E7: Nbr of Hoses: | F7: 1 | K7: Dia of Hoses: | L7: 10" | S7: Dia of Shore line: | T7: 12" | Z7: Dist to shore tank: | AA7: 0.5km
H8: Date/Time Comptd Pumping: | I8: 43009.133 | W8: Date Time Hose disconnected:
P9: Max Rate permitted by receiving facility: | Q9: GASOIL C - 600 M3/HR
P10: Max Pressure permitted by receiving facility: | Q10: 8 Bar
P11: Any other restrictions by receiving facility:
B13: PRESSURE GAUGE TO BE PLACED OUT OF SHIP’S MANIFOLD VALVE - PRESSURE IN BAR / PSI (Strike out one)
B15: Date | D15: Pressure at Ship Rail | N15: Discharge Rate | O15: Temp. | S15: Remarks | AA15: Ch/Off Initials
D16: Manifold Number | O16: Air | Q16: Cargo
B17: Time | F17: #3 | O17: °C | Q17: °C
B18: 0.74583333 | F18: 0 | S18: Commenced loading GASOIL C | AA18: VV
B19: 0.75 | F19: 0 | N19: 11 | O19: 25 | Q19: 26 | AA19: JS
B20: 0.79166667 | F20: 0 | N20: 471 | O20: 24 | Q20: 26 | AA20: JS
B21: 0.83333333 | F21: 0 | N21: 567 | O21: 24 | Q21: 26 | AA21: JS
B22: 0.875 | F22: 0 | N22: 552 | O22: 24 | Q22: 26 | AA22: KG
B23: 0.91666667 | F23: 0 | N23: 552 | O23: 24 | Q23: 26 | AA23: KG
B24: 0.95833333 | F24: 0 | N24: 565 | O24: 24 | Q24: 26 | AA24: KG
B25: 1 | F25: 0 | N25: 546 | O25: 23 | Q25: 25 | AA25: KG
B26: 0.041666667 | F26: 0 | N26: 551 | O26: 22 | Q26: 25 | AA26: IM
B27: 0.083333333 | F27: 0 | N27: 552 | O27: 22 | Q27: 25 | AA27: IM
B28: 0.125 | F28: 0 | N28: 559 | O28: 22 | Q28: 25 | AA28: IM
B29: 0.13333333 | F29: 0 | N29: 111 | O29: 22 | Q29: 25 | S29: Completed loading - SHORE STOP | AA29: IM
AA41: JS
B45: Terminal | I45: Cargo Surveyor | Q45: Chief Mate | X45: Master

Sheet KM1 (ATLANTIS)
E2: KEY TRANSFER MEETING | L2: PRT 011 | M2: Page 1 of 1
L3: Rev : 02 | M3: 42917
B5: Vessel | C5: ATRIA | F5: Port | G5: ='Data Entry'!B13 -> 0 | L5: Voy No | M5: ='Data Entry'!B11 -> 0
B7: Terminal | C7: VOPAK Europort / Barge ATLANTIS | F7: Berth | G7: ='Data Entry'!B23 -> 0 | L7: Date | M7: 43436
B9: Vessel Information | I9: Barge Information
B10: No. and Size of Manifolds | E10: 1 x 16" | I10: No. & Size of Connections
F11: GASOLINE | M11: GASOLINE
B12: SIMULTANEOUS Cargo Transfer Rates | D12: Initial | E12: 300 m3/h | I12: SIMULTANEOUS Cargo Transfer Rates (or) Manifold Pressure | K12: Initial
D13: Bulk | E13: 1000 m3/h or 10Bar | K13: Bulk
D14: Final | E14: 300 m3/h | K14: Final
B15: NON-SIMULTANEOUS Cargo Transfer Rates | D15: Initial | E15: 500 m3/h | F15: 300 m3/h | G15: 300 m3/h | I15: NON- SIMULTANEOUS Cargo Transfer Rates (or) Manifold Pressure | K15: Initial
D16: Bulk | E16: 3000 m3/h or 10Bar | F16: 1500 m3/h or 10Bar | G16: 500 m3/h or 10Bar | K16: Bulk
D17: Final | E17: 500 m3/h | F17: 300 m3/h | G17: 300 m3/h | K17: Final
B18: Emergency Signal by Vessel | I18: Emergency Signal by Terminal
B19: Notice for Immediate Stoppage | E19: N/A - LOADING | I19: Notice for Immediate Stoppage
B20: Notice for Rate Reduction | E20: N/A - LOADING | I20: Notice for Rate Reduction
B21: Tanks to COW | E21: N/A | I21: Cargo Dens.& Temp
B22: Vessel Experience Factor | E22: 0.9986 | I22: Shore Line size and length
I23: Shore tanks number
I24: Line Displacement Requirement
I25: Ship/Shore Communication
C26: Cargo History | I26: Back-Up Communication
C27: Cargo Grade | E27: Tanks Loaded | I27: Emergency Shutdown Procedure
B28: Last | C28: SEE LAST 3 CARGO LIST | I28: Material Safety Data Sheet
B29: 2nd Last | I29: Method of arm/hose draining
B30: 3rd Last | I30: Manifold height above water
I31: Max Depth at Berth
B33: Cargo Stoppage by: (Ship/Shore) | H33: Cargo Grade as per B/L | J33: GASOLINE
H34: BARGE Nomination
H35: Vessels Nomination | J35: ACAP 4300 MT in AIR
B36: Watch Keeping Schedule
B37: Time ® | C37: 00-04 / 12-24 | E37: 04-08 / 16-20 | G37: 08-12 / 20-24
B38: D/Officer | C38: 2/O B. Vergara | E38: 3/O C.Balmes | G38: 4/O T. Join
B39: Crew | C39: AB1 R. Balais | E39: AB2 M. Dimaisip | G39: AB3 B. Perez
B40: Crew | C40: OS R. Longakit | E40: Wiper E. Osayan | G40: BSN E. Echanes
B43: Drafts | C43: Ford | D43: Aft | E43: M'ship | I43: Master's Name | K43: Capt. T. Hemon
B44: Arrival | C44: 6.30 m | D44: 6.90 m | E44: 6.60 m | F44: SW | I44: Chief Engineer's Name | K44: C/E K. Tarasenko
B45: Departure | C45: 10.60 m | D45: 10.60m | E45: 10.60 m | F45: SW | I45: Chief Officer's Name | K45: C/O M.A.Delgado
B47: Tide | I47: Remarks:
B48: Date/Time | C48: Ht. of tide | D48: Date/Time | E48: Ht. of tide | F48: Date/Time | G48: Ht. of tide
...

Sheet KM1 (GERVAIS)
E2: KEY TRANSFER MEETING | L2: PRT 011 | M2: Page 1 of 1
L3: Rev : 02 | M3: 42917
B5: Vessel | C5: ATRIA | F5: Port | G5: ='Data Entry'!B13 -> 0 | L5: Voy No | M5: ='Data Entry'!B11 -> 0
B7: Terminal | C7: VOPAK Europort / Barge GERVAIS | F7: Berth | G7: ='Data Entry'!B23 -> 0 | L7: Date | M7: 43411
B9: Vessel Information | I9: Barge Information
B10: No. and Size of Manifolds | E10: 1 x 16" | I10: No. & Size of Connections | L10: 1 x 8"
F11: GASOIL | L11: GASOIL
B12: SIMULTANEOUS Cargo Transfer Rates | D12: Initial | E12: 115 m3/h | I12: SIMULTANEOUS Cargo Transfer Rates (or) Manifold Pressure | K12: Initial
D13: Bulk | E13: 500 m3/h or 10Bar | K13: Bulk
D14: Final | E14: 250 m3/h | K14: Final
B15: NON-SIMULTANEOUS Cargo Transfer Rates | D15: Initial | E15: 500 m3/h | F15: 300 m3/h | G15: 300 m3/h | I15: NON- SIMULTANEOUS Cargo Transfer Rates (or) Manifold Pressure | K15: Initial
D16: Bulk | E16: 3000 m3/h or 10Bar | F16: 1500 m3/h or 10Bar | G16: 500 m3/h or 10Bar | K16: Bulk
D17: Final | E17: 500 m3/h | F17: 300 m3/h | G17: 300 m3/h | K17: Final
B18: Emergency Signal by Vessel | I18: Emergency Signal by Terminal
B19: Notice for Immediate Stoppage | E19: N/A - LOADING | I19: Notice for Immediate Stoppage
B20: Notice for Rate Reduction | E20: N/A - LOADING | I20: Notice for Rate Reduction
B21: Tanks to COW | E21: N/A | I21: Cargo Dens.& Temp
B22: Vessel Experience Factor | E22: 0.9986 | I22: Shore Line size and length
I23: Shore tanks number
I24: Line Displacement Requirement
I25: Ship/Shore Communication
C26: Cargo History | I26: Back-Up Communication
C27: Cargo Grade | E27: Tanks Loaded | I27: Emergency Shutdown Procedure
B28: Last | C28: SEE LAST 3 CARGO LIST | I28: Material Safety Data Sheet
B29: 2nd Last | I29: Method of arm/hose draining
B30: 3rd Last | I30: Manifold height above water
I31: Max Depth at Berth
B33: Cargo Stoppage by: (Ship/Shore) | H33: Cargo Grade as per B/L | J33: GASOIL
H34: BARGE Nomination
H35: Vessels Nomination | J35: ACAP 800 MT in AIR
B36: Watch Keeping Schedule
B37: Time ® | C37: 00-04 / 12-24 | E37: 04-08 / 16-20 | G37: 08-12 / 20-24
B38: D/Officer | C38: 2/O B. Vergara | E38: 3/O C.Balmes | G38: 4/O T. Join
B39: Crew | C39: AB1 R. Balais | E39: AB2 M. Dimaisip | G39: AB3 B. Perez
B40: Crew | C40: OS R. Longakit | E40: Wiper E. Osayan | G40: BSN E. Echanes
B43: Drafts | C43: Ford | D43: Aft | E43: M'ship | I43: Master's Name | K43: Capt. T. Hemon
B44: Arrival | C44: 6.30 m | D44: 6.90 m | E44: 6.60 m | F44: SW | I44: Chief Engineer's Name | K44: C/E K. Tarasenko
B45: Departure | C45: 10.60 m | D45: 10.60m | E45: 10.60 m | F45: SW | I45: Chief Officer's Name | K45: C/O M.A.Delgado
B47: Tide | I47: Remarks:
B48: Date/Time | C48: Ht. of tide | D48: Date/Time | E48: Ht. of tide | F48: Date/Time | G48: Ht. of tide
...

Sheet Meeting
G1: PRE-LOADING / DISCHARGING MEETING | Y1: Page 1 of 1
V2: Version 2 | Y2: 01/01/2026
A4: Vessel : | C4: =IF('Data Entry'!B8="","",'Data Entry'!B8) | I4: Port : | M4: =IF('Data Entry'!B17="","",'Data Entry'!B17) | V4: Voy No :
A6: Terminal : | C6: =IF('Data Entry'!B19="","",'Data Entry'!B19) | I6: Berth : | M6: =IF('Data Entry'!B23="","",'Data Entry'!B23) | V6: Date : | X6: =TODAY() -> 46025
D9: In case of dangerous goods, delivery of MSDS | R9: Docker's shifts timings including breaks:
D11: Transfer of cargo responsibility as per INCOTERMS:
D12: Onboard / Alongside | R12: How many person per hold?
D14: Remittance of the stowage plan | R14: Time of the last truck of the working day
D16: Sequence loading (groups of pallets) | R16: WhatsApp contact of shore person in charge:
D18: Is there any protection against rain provided for cargo? | R18: Does the Terminal issu the Mate's Receipt?
D20: Safety letter, security routes, to be agreed upon with all parties. | R20: Forklifts condition certificate signed and stamped
D22: Fumigation certificate, if any | R22: Cargo hold certificate signed and stamped
A24: Sequence / Cargo Stages | C24: Location to be loaded | F24: Pallets to be loaded start of sequence | I24: Sequence time estimation | K24: Remaining time estimation | M24: Remaining pallets to load | Y24: Total pallets on board end of sequence
A27: Initial | C27: Ship | F27: 934 | K27: 38h30
A28: 1 | C28: Lower cargo hold Fwd | F28: 165 | I28: 12h22 | K28: 26h08 | M28: Fwd holds | P28: =F30+F32 -> 328 | Y28: =F28+F29 -> 301
C29: Lower cargo hold Aft | F29: 136 | M29: Aft holds | P29: =F31+F33 -> 305
A30: 2 | C30: Middle cargo hold Fwd | F30: 177 | I30: 13h17 | K30: 12h51 | M30: Fwd holds | P30: =P28-F30 -> 151 | Y30: =Y28+F30+F31 -> 634
C31: Middle cargo hold Aft | F31: 156 | M31: Aft holds | P31: =P29-F31 -> 149
A32: 3 | C32: Upper cargo hold Fwd | F32: 151 | I32: 11h19 | K32: 01h32 | M32: Fwd holds | P32: 0 | Y32: =Y30+F32+F33 -> 934
C33: Upper cargo hold Aft | F33: 149 | M33: Aft holds
A34: Final | Y34: =Y32 -> 934
A35: Lashing and Housekeeping | Y35: 1h30
A36: Total time Expected | Y36: 38h30
A37: Loading Sequence 1 : Loading of lower cargo holds: Heel to be managed with Heeling tanks and booms. Sequence 2 : Loading of middle cargo holds: Heel to be managed with Heeling tanks and booms. Empty 1C and 5C. Load BELCO as picture Sequence 3 : Loading of upper cargo holds:Heel can be managed with Heeling tanks and booms. Empty 2C and 3T. After offloading, FillWB5C, empty WB3T
C49: Chief Officer | U49: Terminal Representative
A51: * - For any key information which is not included above, please prepare on a separate sheet and attach to this document

Sheet Forklifts
F1: CONDITION OF FORKLIFTS | S1: Page 1 of 1 | Y1: Instructions
P2: Version 2 | S2: 01/01/2026
Y3: Chief Officer or Master can sign this certificate. This is the assessment of forklift before the Dockers handle them. If damages are noticed at the end of the cargo operations or during the cargo operation, issu a letter of protest accordingly. Forklift number and location: "Aft hold" or "Fwd hold" and number 1 to 4 or serial numbers if identification is not clearly done. Fill as follows:
A4: To: | M4: Vessel: | P4: =IF('Data Entry'!B8="","",'Data Entry'!B8)
B5: =IF('Data Entry'!B19="","",'Data Entry'!B19) | M5: Voyage No:
B6: =IF('Data Entry'!B29="","",'Data Entry'!B29) | M6: Port: | P6: =IF('Data Entry'!B17="","",'Data Entry'!B17)
B7: =IF('Data Entry'!B33="","",'Data Entry'!B33) | M7: Berth: | P7: =IF('Data Entry'!B23="","",'Data Entry'!B23)
B8: =IF('Data Entry'!B31="","",'Data Entry'!B31) | M8: Chrtr Ref. Nbr: | P8: C/P
B9: To whom it may concern
A12: Forklift number and location
A15: List of damages before cargo operations
B41: Dockers' Foreman | P41: Master/Chief Officer

Sheet LOP FP
F1: LETTER OF PROTEST - FREE PRATIQUE | S1: Page 1 of 1 | X1: Instructions
P2: Version 2 | S2: 01/01/2026
X3: Issue this LOP by e-mail immediately after arrival if the Free Pratique is not granted automatically on arrival and if a Free Pratique inspection is required and is causing delays.
A4: To: | M4: Vessel: | P4: =IF('Data Entry'!B8="","",'Data Entry'!B8)
B5: =IF('Data Entry'!B19="","",'Data Entry'!B19) | M5: Voyage No:
B6: =IF('Data Entry'!B29="","",'Data Entry'!B29) | M6: Port: | P6: =IF('Data Entry'!B17="","",'Data Entry'!B17)
B7: =IF('Data Entry'!B33="","",'Data Entry'!B33) | M7: Berth: | P7: =IF('Data Entry'!B23="","",'Data Entry'!B23)
B8: =IF('Data Entry'!B31="","",'Data Entry'!B31) | M8: Chrtr Ref. Nbr: | P8: C/P
B9: To whom it may concern
A12: Dear Sirs,
B13: In order to protect the interests of my owner(s), disponent owner(s) and charterer(s), I must protest the following circumstances:
B15: This is to place on record that | G15: ='Data Entry'!B8 -> 0 | J15: , under my command, has arrived on roads/at berth/anchorage of
G16: (Vessel Name)
B17: ='Data Entry'!B17 -> 0 | I17: on the | Q17: hours local time
B18: (Port, Country) | K18: (Date & Time)
B19: and requested Free Pratique.
B21: However, since free pratique has not been granted on her arrival, on behalf of my disponent owners, charterers and other interested parties, I hereby lodge a protest and hold you liable for all consequential losses, damages, delays and/or claims that may arise due to this fact. We hereby reserve the right to take such further action as may be considered necessary to protect the interest of and also reserve the right to refer to this Letter of Protest at a future date and place convenient to the Owners and / or charterers.
O28: Yours faithfully,
O34: ='Data Entry'!B35 -> 0
O35: Master
B41: Terminal / Receiver-Shipper Representative / Agency Representative
B42: If Receivers / Shippers / Terminal Representative / Agent refuses to sign, please mark 'Refused to Sign'

Sheet LOP Delays
F1: LETTER OF PROTEST - DELAYS & RESTRICTIONS | S1: Page 1 of 1 | X1: Instructions
P2: Version 2 | S2: 01/01/2026
X3: Letters of Protest should be signed by the Master only. Letters of Protest or Notice of Protest of external party should by signed only by the Master with the mention "For receipt only without prejudice". All delays cause by external parties should be protested against: break, working hours not respected, shore forklift break down, pilot, berth… If the cause of the delay is not clear, avoid giving details, just be factual. Avoid detail such as "See Statement of Fact". LOP for delays should be explicite and can be understood without reference to SOF.
A4: To: | M4: Vessel: | P4: =IF('Data Entry'!B8="","",'Data Entry'!B8)
B5: =IF('Data Entry'!B19="","",'Data Entry'!B19) | M5: Voyage No:
B6: =IF('Data Entry'!B29="","",'Data Entry'!B29) | M6: Port: | P6: =IF('Data Entry'!B17="","",'Data Entry'!B17)
B7: =IF('Data Entry'!B33="","",'Data Entry'!B33) | M7: Berth: | P7: =IF('Data Entry'!B23="","",'Data Entry'!B23)
B8: =IF('Data Entry'!B31="","",'Data Entry'!B31) | M8: Chrtr Ref. Nbr: | P8: C/P
B9: To whom it may concern
B12: In order to protect the interests of my owner(s) and charterer(s), I must protest the following circumstances,
M14: Additionnal information
D15: Berth was occupied on arrival
D17: Cargo was not ready on arrival
D19: Delay awaiting commencement of Loading /
D20: Discharging shore readiness
D22: Cargo was loaded slower than ship's capability
D23: Vessel is capable of loading at :
D24: Actual loading rates, provided by terminal:
D26: Delay awaiting Cargo Documents
D28: Additional Delays were incurred as listed below:
B41: And I hereby lodge protest accordingly, and we, including, my disponent owners and/or charterers, hold you responsible for any consequences. On behalf of the owners and / or charterers, I hereby reserve the right to take such further action as may be considered necessary to protect the interest of these parties. I reserve the right to refer to this Letter of Protest at a future date and place convenient to the Owners and / or charterers.
O50: ='Data Entry'!B35 -> 0
O51: Master
B57: Terminal / Receiver-Shipper Representative / Agency Representative
B58: If Receivers / Shippers / Terminal Representative / Agent refuses to sign, please mark 'Refused to Sign'

Sheet LOP Document
F1: LETTER OF PROTEST - DOCUMENTATION | S1: Page 1 of 1 | X1: Instructions
P2: Version 2 | S2: 01/01/2026
X3: Letters of Protest should be signed by the Master only. Letters of Protest or Notice of Protest of external party should by signed only by the Master with the mention "For receipt only without prejudice". MSDS should be provided in the language of importation country and be delivered to the terminal before discharging.
A4: To: | M4: Vessel: | P4: =IF('Data Entry'!B8="","",'Data Entry'!B8)
B5: =IF('Data Entry'!B19="","",'Data Entry'!B19) | M5: Voyage No:
B6: =IF('Data Entry'!B29="","",'Data Entry'!B29) | M6: Port: | P6: =IF('Data Entry'!B17="","",'Data Entry'!B17)
B7: =IF('Data Entry'!B33="","",'Data Entry'!B33) | M7: Berth: | P7: =IF('Data Entry'!B23="","",'Data Entry'!B23)
B8: =IF('Data Entry'!B31="","",'Data Entry'!B31) | M8: Chrtr Ref. Nbr: | P8: C/P
B9: To whom it may concern
B12: In order to protect the interests of my owner(s) and charterer(s), I must protest the following circumstances,
M14: Additionnal information
D15: Terminal shortloaded nominated cargo:
D17: Terminal overloaded nominated cargo:
D19: Vessel was not provided an MSDS for the cargo
D21: Voyage charter party date not mentioned on B/L
D23: No condition of carriage mentioned on the back
D24: page of BL.
D26: Terminal / Shipper representative did not
D27: sign vessels documents
D29: Cargo temperature after loading higher than
D30: instructed:
D32: Additionnal protest:
B41: And I hereby lodge protest accordingly, and we, including, my disponent owners and/or charterers, hold you responsible for any consequences. On behalf of the owners and / or charterers, I hereby reserve the right to take such further action as may be considered necessary to protect the interest of these parties. I reserve the right to refer to this Letter of Protest at a future date and place convenient to the Owners and / or charterers.
O50: ='Data Entry'!B35 -> 0
O51: Master
B57: Terminal / Receiver-Shipper Representative / Agency Representative
B58: If Receivers / Shippers / Terminal Representative / Agent refuses to sign, please mark 'Refused to Sign'

Sheet LOP Q-TY (Oxy)
F2: LETTER OF PROTEST - LOADING (QUANTITY & OTHERS) | L2: PRT 005A | M2: Page 1 of 1
L3: Rev: 02 | M3: 42917
C5: Vessel: | E5: ATRIA | I5: To: | J5: TO WHOM IT MAY CONCERN
C6: Terminal: | E6: ='Data Entry'!B19 -> 0 | J6: =NOR!B6
C7: Date: | E7: =TODAY() -> 46025 | J7: =NOR!B4 -> 0
C8: Voy No: | E8: ='Data Entry'!B11 -> 0
C9: Charterer's Ref No: | F9: =NOR!P7
C10: Cargo Grade: | F10: UMS (OXY)
C12: Dear Sir,
C13: In order to protect the interests of my owner(s) and charterer(s), I must protest the following circumstances, :
C15: X | E15: Shipper forced the following Bills of Lading be issued with figures we do not believe to be accurate:
E16: (Figures adjusted for VEF - N )
C18: VEF APPLIED (MT IN AIR) | K18: VEF NOT APPLIED (MT IN AIR)
C19: GRADE | E19: BL Figures | G19: Ship's Figures | I19: Diff. % | K19: BL Figures | L19: Ship's Figures | M19: Diff %
C20: =F10 -> UMS (OXY) | E20: 4063.281 | G20: 4051.788 | I20: =(G20-E20)/E20*100 -> -0.28285024 | J20: =F10 -> UMS (OXY) | K20: =IF(E20="","",E20) -> 4063.281 | L20: 4046.115 | M20: =(L20-K20)/L20*100 -> -0.42425883
C22: X | E22: Terminal shortloaded nominated cargo: | J22: Nominated: 5650.000 m3 @ 15oC | L22: Loaded : 5623.822 m3 @ 15oC
E24: Terminal overloaded nominated cargo | J24: Nominated: | L24: Loaded:
I26: Additional comments, as applicable:
E28: Voyage charter party date 16 January 2019 not mentioned on B/L, no condition of carriage mentioned on the back page
E30: Terminal / Shipper representative did not
E31: sign vessels documents
E33: Terminal did not sign the vessel's documents
E35: Certificate of Origin not provided
E37: Certificate of Quality not provided
E39: Cargo temperature was outside agreed limits: | I39: Requested (Max/Min): | L39: Observed Temp.:
E41: Oil Sheen on water seen on arrival / at the
E42: berth which has contaminated the hull
C44: X | E44: There was insufficient time for settling after completion of Loading. Vessels tanks had NO water on arrival and tanks | R44: ____________ amount of water was found and/or is further likely to be found in the cargo on settling.
E45: were certified empty and well drained by the Surveyor.
E47: Ullaging was carried out in open sea conditions with the vessel moving and cargo ullage was not steady.
E49: The terminal did not accept Slops
E51: Additional protest (Summary of details as below - full details on separate protest, as deemed necessary)
P52: 1. FINAL DENSITY WAS NOT KNOWN PRIOR OR DURING THE LOADING OPERATION
P53: 2. B/L FIGURES = SHIP'S FIGURES + (SURVEYOR) VEF
C55: And I hereby lodge protest accordingly, and we, including, my disponent owners and/or charterers, hold you responsible for any consequences. On behalf of the owners and / or charterers, I hereby reserve the right to take such further action as may be considered necessary to protect the interest of these parties. I reserve the right to refer to this Letter of Protest at a future date and place convenient to the Owners and / or charterers.
D61: Terminal / Suppliers Representative / Agency Represnetative | L61: =NOR!O33 -> 0
C62: If Shippers / Terminal Representative / Agent refuses to sign, please mark 'Refused to Sign' | L62: Ship's Stamp

Sheet LOP Q-TY (G98)
F2: LETTER OF PROTEST - LOADING (QUANTITY & OTHERS) | L2: PRT 005A | M2: Page 1 of 1
L3: Rev: 02 | M3: 42917
C5: Vessel: | E5: ATRIA | I5: To: | J5: TO WHOM IT MAY CONCERN
C6: Terminal: | E6: ='Data Entry'!B19 -> 0 | J6: =NOR!B6
C7: Date: | E7: =TODAY() -> 46025 | J7: =NOR!B4 -> 0
C8: Voy No: | E8: ='Data Entry'!B11 -> 0
C9: Charterer's Ref No: | F9: =NOR!P7
C10: Cargo Grade: | F10: GASOLINE 98
C12: Dear Sir,
C13: In order to protect the interests of my owner(s) and charterer(s), I must protest the following circumstances, :
C15: X | E15: Shipper forced the following Bills of Lading be issued with figures we do not believe to be accurate:
E16: (Figures adjusted for VEF - N )
C18: VEF APPLIED (MT IN AIR) | K18: VEF NOT APPLIED (MT IN AIR)
C19: GRADE | E19: BL Figures | G19: Ship's Figures | I19: Diff. % | K19: BL Figures | L19: Ship's Figures | M19: Diff %
C20: =F10 -> GASOLINE 98 | E20: 1269.783 | G20: 1266.751 | I20: =(G20-E20)/E20*100 -> -0.23878096 | J20: =F10 -> GASOLINE 98 | K20: =IF(E20="","",E20) -> 1269.783 | L20: 1264.977 | M20: =(L20-K20)/L20*100 -> -0.37992786
C22: X | E22: Terminal shortloaded nominated cargo: | J22: Nominated: 1750.000 m3 @ 15oC | L22: Loaded : 1739.757 m3 @ 15oC
E24: Terminal overloaded nominated cargo | J24: Nominated: | L24: Loaded:
I26: Additional comments, as applicable:
E28: Voyage charter party date 16 January 2019 not mentioned on B/L, no condition of carriage mentioned on the back page
E30: Terminal / Shipper representative did not
E31: sign vessels documents
E33: Terminal did not sign the vessel's documents
E35: Certificate of Origin not provided
E37: Certificate of Quality not provided
E39: Cargo temperature was outside agreed limits: | I39: Requested (Max/Min): | L39: Observed Temp.:
E41: Oil Sheen on water seen on arrival / at the
E42: berth which has contaminated the hull
C44: X | E44: There was insufficient time for settling after completion of Loading. Vessels tanks had NO water on arrival and tanks | R44: ____________ amount of water was found and/or is further likely to be found in the cargo on settling.
E45: were certified empty and well drained by the Surveyor.
E47: Ullaging was carried out in open sea conditions with the vessel moving and cargo ullage was not steady.
E49: The terminal did not accept Slops
E51: Additional protest (Summary of details as below - full details on separate protest, as deemed necessary)
P52: 1. FINAL DENSITY WAS NOT KNOWN PRIOR OR DURING THE LOADING OPERATION
P53: 2. B/L FIGURES = SHIP'S FIGURES + (SURVEYOR) VEF
C55: And I hereby lodge protest accordingly, and we, including, my disponent owners and/or charterers, hold you responsible for any consequences. On behalf of the owners and / or charterers, I hereby reserve the right to take such further action as may be considered necessary to protect the interest of these parties. I reserve the right to refer to this Letter of Protest at a future date and place convenient to the Owners and / or charterers.
D61: Terminal / Suppliers Representative / Agency Represnetative | L61: =NOR!O33 -> 0
C62: If Shippers / Terminal Representative / Agent refuses to sign, please mark 'Refused to Sign' | L62: Ship's Stamp

Sheet LOP Q-TY (BOB)
F2: LETTER OF PROTEST - LOADING (QUANTITY & OTHERS) | L2: PRT 005A | M2: Page 1 of 1
L3: Rev: 02 | M3: 42917
C5: Vessel: | E5: ATRIA | I5: To: | J5: TO WHOM IT MAY CONCERN
C6: Terminal: | E6: ='Data Entry'!B19 -> 0 | J6: =NOR!B6
C7: Date: | E7: =TODAY() -> 46025 | J7: =NOR!B4 -> 0
C8: Voy No: | E8: ='Data Entry'!B11 -> 0
C9: Charterer's Ref No: | F9: =NOR!P7
C10: Cargo Grade: | F10: UMS (BOB)
C12: Dear Sir,
C13: In order to protect the interests of my owner(s) and charterer(s), I must protest the following circumstances, :
C15: X | E15: Shipper forced the following Bills of Lading be issued with figures we do not believe to be accurate:
E16: (Figures adjusted for VEF - N )
C18: VEF APPLIED (MT IN AIR) | K18: VEF NOT APPLIED (MT IN AIR)
C19: GRADE | E19: BL Figures | G19: Ship's Figures | I19: Diff. % | K19: BL Figures | L19: Ship's Figures | M19: Diff %
C20: =F10 -> UMS (BOB) | E20: 3947.99 | G20: 3942.541 | I20: =(G20-E20)/E20*100 -> -0.1380196 | J20: =F10 -> UMS (BOB) | K20: =IF(E20="","",E20) -> 3947.99 | L20: 3937.022 | M20: =(L20-K20)/L20*100 -> -0.2785862
C22: X | E22: Terminal shortloaded nominated cargo: | J22: Nominated: 5500.000 m3 @ 15oC | L22: Loaded : 5473.407 m3 @ 15oC
E24: Terminal overloaded nominated cargo | J24: Nominated: | L24: Loaded:
I26: Additional comments, as applicable:
E28: Voyage charter party date 16 January 2019 not mentioned on B/L, no condition of carriage mentioned on the back page
E30: Terminal / Shipper representative did not
E31: sign vessels documents
E33: Terminal did not sign the vessel's documents
E35: Certificate of Origin not provided
E37: Certificate of Quality not provided
E39: Cargo temperature was outside agreed limits: | I39: Requested (Max/Min): | L39: Observed Temp.:
E41: Oil Sheen on water seen on arrival / at the
E42: berth which has contaminated the hull
C44: X | E44: There was insufficient time for settling after completion of Loading. Vessels tanks had NO water on arrival and tanks | R44: ____________ amount of water was found and/or is further likely to be found in the cargo on settling.
E45: were certified empty and well drained by the Surveyor.
E47: Ullaging was carried out in open sea conditions with the vessel moving and cargo ullage was not steady.
E49: The terminal did not accept Slops
E51: Additional protest (Summary of details as below - full details on separate protest, as deemed necessary)
P52: 1. FINAL DENSITY WAS NOT KNOWN PRIOR OR DURING THE LOADING OPERATION
P53: 2. B/L FIGURES = SHIP'S FIGURES + (SURVEYOR) VEF
C55: And I hereby lodge protest accordingly, and we, including, my disponent owners and/or charterers, hold you responsible for any consequences. On behalf of the owners and / or charterers, I hereby reserve the right to take such further action as may be considered necessary to protect the interest of these parties. I reserve the right to refer to this Letter of Protest at a future date and place convenient to the Owners and / or charterers.
D61: Terminal / Suppliers Representative / Agency Represnetative | L61: =NOR!O33 -> 0
C62: If Shippers / Terminal Representative / Agent refuses to sign, please mark 'Refused to Sign' | L62: Ship's Stamp

Sheet LOP DELAYS (GASOLINE)
F2: LETTER OF PROTEST - LOADING (DELAYS & RESTRICTIONS) | L2: PRT 005 | M2: Page 1 of 1
L3: Rev: 02 | M3: 42917
C5: Vessel: | E5: ATRIA | I5: To: | J5: TO WHOM IT MAY CONCERN
C6: Terminal: | E6: ='Data Entry'!B19 -> 0 | J6: =NOR!B6
C7: Date: | E7: =TODAY() -> 46025 | J7: Barge Atalntis
C8: Voy No: | E8: ='Data Entry'!B11 -> 0
C9: Charterer's Ref No: | F9: =NOR!P7
C10: Cargo Grade: | F10: GASOLINE
C12: In order to protect the interests of my owner(s) and charterer(s), I must protest the following circumstances,
I14: Additional comments, as applicable:
E15: Berth was not available on arrival due to terminal readiness
E17: Port authority delays were incurred
C19: X | E19: Delay awaiting commencement of Loading | I19: From 01 Dec 2018; 17:48 LT (NORT) till 02 Dec 2018; 17:42 LT (Commenced loading)
E20: / Barge Readiness
C22: X | E22: Terminal connections to my vessel were restricted
E23: Actual Connections: | H23: 1 | K23: Size: | L23: 8"
E24: My vessel's capability: | H24: 1 | K24: Size: | L24: 16"
C26: X | E26: Cargo was loaded slower than ship's capability
E27: Vessel is capable of loading at : | J27: 1000 m3/hr
E28: Actual loading rate, provided by Barge: | J28: 829 m3/hr
E30: The vessel was able to load multiple grade / parcels simultaneously. The terminal was not able to load all
E31: simultaneously - one by one only, causing additional delays.
I33: EDP Applied
C34: X | E34: Delay awaiting Cargo Documents
E36: Additional Delays were incurred as listed below:
Q37: From 03Dec2018; 02:30LT to **Dec2018; **:**LT - Awaiting Cargo Documents
Q38: From **Dec2018; **:**LT Cargo documents on board to POB
E45: Additional protest 1 (Summary of details as below - full details on separate protest, as deemed necessary)
E49: Additional protest 2 (Summary of details as below - full details on separate protest, as deemed necessary)
C52: And I hereby lodge protest accordingly, and we, including, my disponent owners and/or charterers, hold you responsible for any consequences. On behalf of the owners and / or charterers, I hereby reserve the right to take such further action as may be considered necessary to protect the interest of these parties. I reserve the right to refer to this Letter of Protest at a future date and place convenient to the Owners and / or charterers.
D55: Terminal / Suppliers Representative / Agency Represnetative | L55: =NOR!O33 -> 0
C56: If Shippers / Terminal Representative / Agent refuses to sign, please mark 'Refused to Sign' | L56: Ship's Stamp

Sheet LOP DELAYS (GASOIL)
F2: LETTER OF PROTEST - LOADING (DELAYS & RESTRICTIONS) | L2: PRT 005 | M2: Page 1 of 1
L3: Rev: 02 | M3: 42917
C5: Vessel: | E5: ATRIA | I5: To: | J5: TO WHOM IT MAY CONCERN
C6: Terminal: | E6: ='Data Entry'!B19 -> 0 | J6: =NOR!B6
C7: Date: | E7: =TODAY() -> 46025 | J7: Barge GERVAIS
C8: Voy No: | E8: ='Data Entry'!B11 -> 0
C9: Charterer's Ref No: | F9: =NOR!P7
C10: Cargo Grade: | F10: GASOIL
C12: In order to protect the interests of my owner(s) and charterer(s), I must protest the following circumstances,
I14: Additional comments, as applicable:
E15: Berth was not available on arrival due to terminal readiness
E17: Port authority delays were incurred
C19: X | E19: Delay awaiting commencement of Loading | I19: From 01 Dec 2018; 17:48 LT (NORT) till 05 Dec 2018; 18:06 LT (Commenced loading)
E20: / Barge Readiness
C22: X | E22: Terminal connections to my vessel were restricted
E23: Actual Connections: | H23: 1 | K23: Size: | L23: 8"
E24: My vessel's capability: | H24: 1 | K24: Size: | L24: 16"
C26: X | E26: Cargo was loaded slower than ship's capability
E27: Vessel is capable of loading at : | J27: 500 m3/hr
E28: Actual loading rate, provided by Barge: | J28: 419 m3/hr
E30: The vessel was able to load multiple grade / parcels simultaneously. The terminal was not able to load all
E31: simultaneously - one by one only, causing additional delays.
I33: EDP Applied
E34: Delay awaiting Cargo Documents
C36: X | E36: Additional Delays were incurred as listed below:
P37: From 05Dec2018; 21:12LT to **Dec2018; **:**LT - Awaiting Cargo Documents
P38: From **Dec2018; **:**LT Cargo documents on board to POB
E45: Additional protest 1 (Summary of details as below - full details on separate protest, as deemed necessary)
E49: Additional protest 2 (Summary of details as below - full details on separate protest, as deemed necessary)
C52: And I hereby lodge protest accordingly, and we, including, my disponent owners and/or charterers, hold you responsible for any consequences. On behalf of the owners and / or charterers, I hereby reserve the right to take such further action as may be considered necessary to protect the interest of these parties. I reserve the right to refer to this Letter of Protest at a future date and place convenient to the Owners and / or charterers.
D55: Terminal / Suppliers Representative / Agency Represnetative | L55: =NOR!O33 -> 0
C56: If Shippers / Terminal Representative / Agent refuses to sign, please mark 'Refused to Sign' | L56: Ship's Stamp

Sheet LOP Deadfreightg
F1: LETTER OF PROTEST - DEADFREIGHT | S1: Page 1 of 1 | X1: Instructions
P2: Version 2 | S2: 01/01/2026
X3: Letters of Protest should be signed by the Master only. Letters of Protest or Notice of Protest of external party should by signed only by the Master with the mention "For receipt only without prejudice". If the vessel is not fully loaded, issue this letter of protest stating the deadfreight: difference between ship capacity and actual quantity of cargo.
A4: To: | M4: Vessel: | P4: =IF('Data Entry'!B8="","",'Data Entry'!B8)
B5: =IF('Data Entry'!B19="","",'Data Entry'!B19) | M5: Voyage No:
B6: =IF('Data Entry'!B29="","",'Data Entry'!B29) | M6: Port: | P6: =IF('Data Entry'!B17="","",'Data Entry'!B17)
B7: =IF('Data Entry'!B33="","",'Data Entry'!B33) | M7: Berth: | P7: =IF('Data Entry'!B23="","",'Data Entry'!B23)
B8: =IF('Data Entry'!B31="","",'Data Entry'!B31) | M8: Chrtr Ref. Nbr: | P8: C/P
B9: To whom it may concern
B12: In order to protect the interests of my owner(s) and charterer(s), I must protest the following circumstances,
B14: Please be informed that after completion of loading, deadfreight is as follows
B17: Quantity as per Max Allowable Intake: | N17: MT
N18: Pallets
B19: Quantity loaded as per B/L: | N19: MT
N20: Pallets
B23: Deadfreight: | N23: MT
N24: Pallets
B28: And I hereby lodge protest accordingly, and we, including, my disponent owners and/or charterers, hold you responsible for any consequences. On behalf of the owners and / or charterers, I hereby reserve the right to take such further action as may be considered necessary to protect the interest of these parties. I reserve the right to refer to this Letter of Protest at a future date and place convenient to the Owners and / or charterers.
O37: ='Data Entry'!B35 -> 0
O38: Master
B44: Terminal / Receiver-Shipper Representative / Agency Representative
B45: If Receivers / Shippers / Terminal Representative / Agent refuses to sign, please mark 'Refused to Sign'

Sheet Other LOP
F1: LETTER OF PROTEST | S1: Page 1 of 1 | X1: Instructions
P2: Version 2 | S2: 01/01/2026
X3: Letters of Protest should be signed by the Master only. Letters of Protest or Notice of Protest of external party should by signed only by the Master with the mention "For receipt only without prejudice".
A4: To: | B4: Name of Charterer | M4: Vessel: | P4: =IF('Data Entry'!B8="","",'Data Entry'!B8)
B5: =IF('Data Entry'!B19="","",'Data Entry'!B19) | M5: Voyage No:
B6: =IF('Data Entry'!B29="","",'Data Entry'!B29) | M6: Port: | P6: =IF('Data Entry'!B17="","",'Data Entry'!B17)
B7: =IF('Data Entry'!B33="","",'Data Entry'!B33) | M7: Berth: | P7: =IF('Data Entry'!B23="","",'Data Entry'!B23)
B8: =IF('Data Entry'!B31="","",'Data Entry'!B31) | M8: Chrtr Ref. Nbr: | P8: C/P
B9: To whom it may concern
B12: In order to protect the interests of my owner(s) and charterer(s), I must protest the following circumstances,
